Workbook

Sheet 說明
A1: Ch08 巨量資料與開放資料 — 試算表教學範例
A2: 城市科技｜資料清理、篩選排序、統計函數、資料視覺化
A4: 【資料說明】
A5: 本檔的 YouBike 站點資料為「教學模擬資料」，站名取自真實地點，但數字是為了練習而產生，不代表官方統計。
A6: 真實資料可到 臺北市資料大平臺（data.taipei）或 政府資料開放平臺（data.gov.tw）搜尋「YouBike」下載 CSV。
A8: 【工作表與上課流程】
A9: ① 原始資料：故意放了 6 種「髒資料」（紅底），先讓學生找找看有哪些問題。
A10: ② 清理步驟：用 TRIM、IF、SUBSTITUTE、VALUE、COUNTIFS 一欄一欄修正，藍底儲存格都是公式。
A11: ③ 清理後：清理完成的乾淨資料，已開啟「篩選」，可練習排序與篩選。
A12: ④ 篩選練習：自動篩選與進階篩選的題目（附答案數量讓學生自我檢核）。
A13: ⑤ 統計：AVERAGE、MEDIAN、MODE、STDEV、MAX、MIN、COUNTIF、SUMIF、AVERAGEIF，以及「平均 vs 中位數」的薪資例子。
A14: ⑥ 時段資料：平日與假日每小時借車次數，用來畫折線圖。
... A26: 【Google 試算表】檔案 → 匯入 → 上傳本檔即可使用；公式與圖表都相容（樞紐分析在 Ch09）。

Sheet 原始資料
A1: 原始資料（含髒資料）
A2: 模擬從開放資料平臺下載的 CSV：紅底是有問題的儲存格，上課時可先把紅底取消，讓學生自己找
A4: 站點編號 | B4: 站點名稱 | C4: 行政區 | D4: 車柱數 | E4: 9月借車次數 | F4: 9月還車次數
A5: 500101021 | B5: YouBike2.0_捷運台電大樓站(2號出口) | C5: 中正區 | D5: 30 | E5: 3238 | F5: 3262
A6: 500101045 | B6: YouBike2.0_臺大醫院 | C6: 中正區 | D6: 76 | E6: 8621 | F6: 8705
A7: 500101066 | B7: YouBike2.0_中正紀念堂 | C7: 中正區 | D7: 60 | E7: 6959 | F7: 6659
A8: 500101090 | B8: YouBike2.0_捷運古亭站(5號出口) | C8: 中正區 | D8: 44 | E8: 2939 | F8: 2969
A9: 500101090 | B9: YouBike2.0_捷運古亭站(5號出口) | C9: 中正區 | D9: 44 | E9: 2939 | F9: 2969
A10: 500101102 | B10: YouBike2.0_捷運雙連站(1號出口) | C10: 大同區 | D10: 20 | E10: 1246 | F10: 1325
A11: 500101116 | B11: YouBike2.0_大稻埕碼頭 | C11: 大同區 | D11: 44 | E11: 3644 | F11: 3708
A12: 500101129 | B12: YouBike2.0_捷運圓山站(2號出口) | C12: 大同區 | D12: 28 | E12: 2481 | F12: 2495
A13: 500101141 | B13: YouBike2.0_捷運中山站(4號出口) | C13: 中山 | D13: 76 | E13: 8177 | F13: 8716
A14: 500101171 | B14: YouBike2.0_行天宮 | C14: 中山區 | D14: 20 | E14: 1904 | F14: 1914
A15: 500101189 | B15: YouBike2.0_捷運民權西路站(9號出口) | C15: 中山區 | D15: 76 | E15: 7936 | F15: 8277
A16: 500101206 | B16: YouBike2.0_花博公園 | C16: 中山區 | D16: 32 | E16: 3,259 | F16: 3201
A17: 500101232 | B17: YouBike2.0_捷運南京三民站 | C17: 松山區 | D17: 48 | E17: 4237 | F17: 4218
A18: 500101256 | B18: YouBike2.0_松山車站 | C18: 松山區 | D18: 28 | F18: 2533
A19: 500101284 | B19: YouBike2.0_臺北小巨蛋 | C19: 松山區 | D19: 68 | E19: 5118 | F19: 5342
A20: 500101315 | B20: YouBike2.0_捷運公館站(2號出口) | C20: 大安區 | D20: 32 | E20: 3607 | F20: 3624
A21: 500101315 | B21: YouBike2.0_捷運公館站(2號出口) | C21: 大安區 | D21: 32 | E21: 3607 | F21: 3624
A22: 500101326 | B22: YouBike2.0_臺大總圖 | C22: 大安區 | D22: 52 | E22: 6518 | F22: 6201
A23: 500101363 | B23: YouBike2.0_捷運大安站 | C23: 大安區 | D23: 60 | E23: 8885 | F23: 8100
A24: 500101371 | B24: YouBike2.0_師大分部 | C24: 大安區 | D24: 40 | E24: 5959 | F24: 5394
A25: 500101382 | B25: YouBike2.0_捷運忠孝復興站 | C25: 大安區 | D25: 20 | E25: 3598 | F25: 3886
A26: 500101403 | B26: YouBike2.0_大安森林公園 | C26: 大安區 | D26: 40 | E26: 99999 | F26: 7074
A27: 500101424 | B27: YouBike2.0_捷運龍山寺站 | C27: 萬華區 | D27: 36 | E27: 3315 | F27: 3097
A28: 500101430 | B28: YouBike2.0_西門町 | C28: 信義 | D28: 48 | E28: 2795 | F28: 2854
A29: 500101437 | B29: YouBike2.0_青年公園 | C29: 萬華區 | D29: 36 | E29: 2861 | F29: 3044
A30: 500101458 | B30: YouBike2.0_捷運市政府站 | C30: 信義區 | D30: 48 | E30: 5349 | F30: 5358
... A32: 500101534 | B32: YouBike2.0_松山文創園區 | C32: 信義區 | D32: 48 | E32: 4795 | F32: 5173
A33: 500101548 | B33: YouBike2.0_捷運永春站 | C33: 信義區 | D33: 32 | E33: 3243 | F33: 3,244
A34: 500101580 | B34: YouBike2.0_捷運士林站 | C34: 士林區 | D34: 48 | E34: 4366 | F34: 4052
A35: 500101586 | B35: YouBike2.0_捷運劍潭站 | C35: 士林區 | D35: 28 | E35: 2584 | F35: 2379
A36: 500101622 | B36: YouBike2.0_天母運動公園 | C36: 士林區 | D36: 30 | E36: 2563 | F36: 2558
A37: 500101627 | B37: YouBike2.0_捷運北投站 | C37: 北投區 | D37: 28 | E37: 1502 | F37: 1604
A38: 500101655 | B38: YouBike2.0_新北投 | C38: 北投區 | D38: 44 | E38: 2671 | F38: 2801
A39: 500101670 | B39: YouBike2.0_捷運石牌站 | C39: 北投區 | D39: 20 | E39: 1381 | F39: 1490
A40: 500101701 | B40: YouBike2.0_捷運內湖站 | C40: 內湖區 | D40: 76 | E40: 6391 | F40: 6725
A41: 500101737 | B41: YouBike2.0_內湖科學園區 | C41: 內湖區 | D41: 60 | E41: 3880
A42: 500101759 | B42: YouBike2.0_捷運大湖公園站 | C42: 內湖區 | D42: 28 | E42: 2737 | F42: 2993
...

Sheet 清理步驟
A1: 清理步驟（每一欄都是公式）
A2: 藍底是公式：選一格看公式列，再往下拉就會套用到整欄
A4: 站點編號 | B4: 站點名稱 =TRIM() | C4: 行政區 =TRIM()＋補「區」 | D4: 車柱數 | E4: 借車次數 文字轉數字 | F4: 還車次數 文字轉數字 | G4: 是否重複 =COUNTIFS() | H4: 缺值？ | I4: 異常值？ 借車>20000 | J4: 保留？ | L4: 上課提示： 1. 先只做 B、C 欄（TRIM），讓學生看到空白不見了。 2. E、F 欄示範 SUBSTITUTE 去逗號、VALUE 轉數字。 3. G 欄 COUNTIFS 的範圍 $A$5:A5 是「到目前這列為止」，所以只有第 2 次出現才標「重複」。 4. 最後用 J 欄篩選「✘ 刪除」，就知道要刪哪幾列。 5. 要把公式結果變成資料：複製 → 選擇性貼上 → 值。
A5: =原始資料!A5 -> 500101021 | B5: =TRIM(原始資料!B5) -> YouBike2.0_捷運台電大樓站(2號出口) | C5: =IF(RIGHT(TRIM(原始資料!C5),1)="區",TRIM(原始資料!C5),TRIM(原始資料!C5)&"區") -> 中正區 | D5: =原始資料!D5 -> 30 | E5: =IF(原始資料!E5="","",VALUE(SUBSTITUTE(原始資料!E5,",",""))) -> 3238 | F5: =IF(原始資料!F5="","",VALUE(SUBSTITUTE(原始資料!F5,",",""))) -> 3262 | G5: =IF(COUNTIFS($A$5:A5,A5,$B$5:B5,B5)>1,"重複","") | H5: =IF(OR(E5="",F5=""),"缺值","") | I5: =IF(AND(E5<>"",E5>20000),"異常","") | J5: =IF(AND(G5="",H5="",I5=""),"✔ 保留","✘ 刪除") -> ✔ 保留
A6: =原始資料!A6 -> 500101045 | B6: =TRIM(原始資料!B6) -> YouBike2.0_臺大醫院 | C6: =IF(RIGHT(TRIM(原始資料!C6),1)="區",TRIM(原始資料!C6),TRIM(原始資料!C6)&"區") -> 中正區 | D6: =原始資料!D6 -> 76 | E6: =IF(原始資料!E6="","",VALUE(SUBSTITUTE(原始資料!E6,",",""))) -> 8621 | F6: =IF(原始資料!F6="","",VALUE(SUBSTITUTE(原始資料!F6,",",""))) -> 8705 | G6: =IF(COUNTIFS($A$5:A6,A6,$B$5:B6,B6)>1,"重複","") | H6: =IF(OR(E6="",F6=""),"缺值","") | I6: =IF(AND(E6<>"",E6>20000),"異常","") | J6: =IF(AND(G6="",H6="",I6=""),"✔ 保留","✘ 刪除") -> ✔ 保留
A7: =原始資料!A7 -> 500101066 | B7: =TRIM(原始資料!B7) -> YouBike2.0_中正紀念堂 | C7: =IF(RIGHT(TRIM(原始資料!C7),1)="區",TRIM(原始資料!C7),TRIM(原始資料!C7)&"區") -> 中正區 | D7: =原始資料!D7 -> 60 | E7: =IF(原始資料!E7="","",VALUE(SUBSTITUTE(原始資料!E7,",",""))) -> 6959 | F7: =IF(原始資料!F7="","",VALUE(SUBSTITUTE(原始資料!F7,",",""))) -> 6659 | G7: =IF(COUNTIFS($A$5:A7,A7,$B$5:B7,B7)>1,"重複","") | H7: =IF(OR(E7="",F7=""),"缺值","") | I7: =IF(AND(E7<>"",E7>20000),"異常","") | J7: =IF(AND(G7="",H7="",I7=""),"✔ 保留","✘ 刪除") -> ✔ 保留
A8: =原始資料!A8 -> 500101090 | B8: =TRIM(原始資料!B8) -> YouBike2.0_捷運古亭站(5號出口) | C8: =IF(RIGHT(TRIM(原始資料!C8),1)="區",TRIM(原始資料!C8),TRIM(原始資料!C8)&"區") -> 中正區 | D8: =原始資料!D8 -> 44 | E8: =IF(原始資料!E8="","",VALUE(SUBSTITUTE(原始資料!E8,",",""))) -> 2939 | F8: =IF(原始資料!F8="","",VALUE(SUBSTITUTE(原始資料!F8,",",""))) -> 2969 | G8: =IF(COUNTIFS($A$5:A8,A8,$B$5:B8,B8)>1,"重複","") | H8: =IF(OR(E8="",F8=""),"缺值","") | I8: =IF(AND(E8<>"",E8>20000),"異常","") | J8: =IF(AND(G8="",H8="",I8=""),"✔ 保留","✘ 刪除") -> ✔ 保留
A9: =原始資料!A9 -> 500101090 | B9: =TRIM(原始資料!B9) -> YouBike2.0_捷運古亭站(5號出口) | C9: =IF(RIGHT(TRIM(原始資料!C9),1)="區",TRIM(原始資料!C9),TRIM(原始資料!C9)&"區") -> 中正區 | D9: =原始資料!D9 -> 44 | E9: =IF(原始資料!E9="","",VALUE(SUBSTITUTE(原始資料!E9,",",""))) -> 2939 | F9: =IF(原始資料!F9="","",VALUE(SUBSTITUTE(原始資料!F9,",",""))) -> 2969 | G9: =IF(COUNTIFS($A$5:A9,A9,$B$5:B9,B9)>1,"重複","") -> 重複 | H9: =IF(OR(E9="",F9=""),"缺值","") | I9: =IF(AND(E9<>"",E9>20000),"異常","") | J9: =IF(AND(G9="",H9="",I9=""),"✔ 保留","✘ 刪除") -> ✘ 刪除
A10: =原始資料!A10 -> 500101102 | B10: =TRIM(原始資料!B10) -> YouBike2.0_捷運雙連站(1號出口) | C10: =IF(RIGHT(TRIM(原始資料!C10),1)="區",TRIM(原始資料!C10),TRIM(原始資料!C10)&"區") -> 大同區 | D10: =原始資料!D10 -> 20 | E10: =IF(原始資料!E10="","",VALUE(SUBSTITUTE(原始資料!E10,",",""))) -> 1246 | F10: =IF(原始資料!F10="","",VALUE(SUBSTITUTE(原始資料!F10,",",""))) -> 1325 | G10: =IF(COUNTIFS($A$5:A10,A10,$B$5:B10,B10)>1,"重複","") | H10: =IF(OR(E10="",F10=""),"缺值","") | I10: =IF(AND(E10<>"",E10>20000),"異常","") | J10: =IF(AND(G10="",H10="",I10=""),"✔ 保留","✘ 刪除") -> ✔ 保留
A11: =原始資料!A11 -> 500101116 | B11: =TRIM(原始資料!B11) -> YouBike2.0_大稻埕碼頭 | C11: =IF(RIGHT(TRIM(原始資料!C11),1)="區",TRIM(原始資料!C11),TRIM(原始資料!C11)&"區") -> 大同區 | D11: =原始資料!D11 -> 44 | E11: =IF(原始資料!E11="","",VALUE(SUBSTITUTE(原始資料!E11,",",""))) -> 3644 | F11: =IF(原始資料!F11="","",VALUE(SUBSTITUTE(原始資料!F11,",",""))) -> 3708 | G11: =IF(COUNTIFS($A$5:A11,A11,$B$5:B11,B11)>1,"重複","") | H11: =IF(OR(E11="",F11=""),"缺值","") | I11: =IF(AND(E11<>"",E11>20000),"異常","") | J11: =IF(AND(G11="",H11="",I11=""),"✔ 保留","✘ 刪除") -> ✔ 保留
A12: =原始資料!A12 -> 500101129 | B12: =TRIM(原始資料!B12) -> YouBike2.0_捷運圓山站(2號出口) | C12: =IF(RIGHT(TRIM(原始資料!C12),1)="區",TRIM(原始資料!C12),TRIM(原始資料!C12)&"區") -> 大同區 | D12: =原始資料!D12 -> 28 | E12: =IF(原始資料!E12="","",VALUE(SUBSTITUTE(原始資料!E12,",",""))) -> 2481 | F12: =IF(原始資料!F12="","",VALUE(SUBSTITUTE(原始資料!F12,",",""))) -> 2495 | G12: =IF(COUNTIFS($A$5:A12,A12,$B$5:B12,B12)>1,"重複","") | H12: =IF(OR(E12="",F12=""),"缺值","") | I12: =IF(AND(E12<>"",E12>20000),"異常","") | J12: =IF(AND(G12="",H12="",I12=""),"✔ 保留","✘ 刪除") -> ✔ 保留
A13: =原始資料!A13 -> 500101141 | B13: =TRIM(原始資料!B13) -> YouBike2.0_捷運中山站(4號出口) | C13: =IF(RIGHT(TRIM(原始資料!C13),1)="區",TRIM(原始資料!C13),TRIM(原始資料!C13)&"區") -> 中山區 | D13: =原始資料!D13 -> 76 | E13: =IF(原始資料!E13="","",VALUE(SUBSTITUTE(原始資料!E13,",",""))) -> 8177 | F13: =IF(原始資料!F13="","",VALUE(SUBSTITUTE(原始資料!F13,",",""))) -> 8716 | G13: =IF(COUNTIFS($A$5:A13,A13,$B$5:B13,B13)>1,"重複","") | H13: =IF(OR(E13="",F13=""),"缺值","") | I13: =IF(AND(E13<>"",E13>20000),"異常","") | J13: =IF(AND(G13="",H13="",I13=""),"✔ 保留","✘ 刪除") -> ✔ 保留
A14: =原始資料!A14 -> 500101171 | B14: =TRIM(原始資料!B14) -> YouBike2.0_行天宮 | C14: =IF(RIGHT(TRIM(原始資料!C14),1)="區",TRIM(原始資料!C14),TRIM(原始資料!C14)&"區") -> 中山區 | D14: =原始資料!D14 -> 20 | E14: =IF(原始資料!E14="","",VALUE(SUBSTITUTE(原始資料!E14,",",""))) -> 1904 | F14: =IF(原始資料!F14="","",VALUE(SUBSTITUTE(原始資料!F14,",",""))) -> 1914 | G14: =IF(COUNTIFS($A$5:A14,A14,$B$5:B14,B14)>1,"重複","") | H14: =IF(OR(E14="",F14=""),"缺值","") | I14: =IF(AND(E14<>"",E14>20000),"異常","") | J14: =IF(AND(G14="",H14="",I14=""),"✔ 保留","✘ 刪除") -> ✔ 保留
A15: =原始資料!A15 -> 500101189 | B15: =TRIM(原始資料!B15) -> YouBike2.0_捷運民權西路站(9號出口) | C15: =IF(RIGHT(TRIM(原始資料!C15),1)="區",TRIM(原始資料!C15),TRIM(原始資料!C15)&"區") -> 中山區 | D15: =原始資料!D15 -> 76 | E15: =IF(原始資料!E15="","",VALUE(SUBSTITUTE(原始資料!E15,",",""))) -> 7936 | F15: =IF(原始資料!F15="","",VALUE(SUBSTITUTE(原始資料!F15,",",""))) -> 8277 | G15: =IF(COUNTIFS($A$5:A15,A15,$B$5:B15,B15)>1,"重複","") | H15: =IF(OR(E15="",F15=""),"缺值","") | I15: =IF(AND(E15<>"",E15>20000),"異常","") | J15: =IF(AND(G15="",H15="",I15=""),"✔ 保留","✘ 刪除") -> ✔ 保留
A16: =原始資料!A16 -> 500101206 | B16: =TRIM(原始資料!B16) -> YouBike2.0_花博公園 | C16: =IF(RIGHT(TRIM(原始資料!C16),1)="區",TRIM(原始資料!C16),TRIM(原始資料!C16)&"區") -> 中山區 | D16: =原始資料!D16 -> 32 | E16: =IF(原始資料!E16="","",VALUE(SUBSTITUTE(原始資料!E16,",",""))) -> 3259 | F16: =IF(原始資料!F16="","",VALUE(SUBSTITUTE(原始資料!F16,",",""))) -> 3201 | G16: =IF(COUNTIFS($A$5:A16,A16,$B$5:B16,B16)>1,"重複","") | H16: =IF(OR(E16="",F16=""),"缺值","") | I16: =IF(AND(E16<>"",E16>20000),"異常","") | J16: =IF(AND(G16="",H16="",I16=""),"✔ 保留","✘ 刪除") -> ✔ 保留
... A50: =原始資料!A50 -> 500101920 | B50: =TRIM(原始資料!B50) -> YouBike2.0_動物園 | C50: =IF(RIGHT(TRIM(原始資料!C50),1)="區",TRIM(原始資料!C50),TRIM(原始資料!C50)&"區") -> 文山區 | D50: =原始資料!D50 -> 30 | E50: =IF(原始資料!E50="","",VALUE(SUBSTITUTE(原始資料!E50,",",""))) -> 2538 | F50: =IF(原始資料!F50="","",VALUE(SUBSTITUTE(原始資料!F50,",",""))) -> 2729 | G50: =IF(COUNTIFS($A$5:A50,A50,$B$5:B50,B50)>1,"重複","") | H50: =IF(OR(E50="",F50=""),"缺值","") | I50: =IF(AND(E50<>"",E50>20000),"異常","") | J50: =IF(AND(G50="",H50="",I50=""),"✔ 保留","✘ 刪除") -> ✔ 保留

Sheet 清理後
A1: 清理後資料
A2: 刪除重複 3 筆、缺值 2 筆、異常值 1 筆後，剩 40 站；已開啟篩選
A4: 站點編號 | B4: 站點名稱 | C4: 行政區 | D4: 車柱數 | E4: 9月借車次數 | F4: 9月還車次數 | G4: 每柱借車次數
A5: 500101021 | B5: YouBike2.0_捷運台電大樓站(2號出口) | C5: 中正區 | D5: 30 | E5: 3238 | F5: 3262 | G5: =ROUND(E5/D5,1) -> 107.9
A6: 500101045 | B6: YouBike2.0_臺大醫院 | C6: 中正區 | D6: 76 | E6: 8621 | F6: 8705 | G6: =ROUND(E6/D6,1) -> 113.4
A7: 500101066 | B7: YouBike2.0_中正紀念堂 | C7: 中正區 | D7: 60 | E7: 6959 | F7: 6659 | G7: =ROUND(E7/D7,1) -> 116
A8: 500101090 | B8: YouBike2.0_捷運古亭站(5號出口) | C8: 中正區 | D8: 44 | E8: 2939 | F8: 2969 | G8: =ROUND(E8/D8,1) -> 66.8
A9: 500101102 | B9: YouBike2.0_捷運雙連站(1號出口) | C9: 大同區 | D9: 20 | E9: 1246 | F9: 1325 | G9: =ROUND(E9/D9,1) -> 62.3
A10: 500101116 | B10: YouBike2.0_大稻埕碼頭 | C10: 大同區 | D10: 44 | E10: 3644 | F10: 3708 | G10: =ROUND(E10/D10,1) -> 82.8
A11: 500101129 | B11: YouBike2.0_捷運圓山站(2號出口) | C11: 大同區 | D11: 28 | E11: 2481 | F11: 2495 | G11: =ROUND(E11/D11,1) -> 88.6
A12: 500101141 | B12: YouBike2.0_捷運中山站(4號出口) | C12: 中山區 | D12: 76 | E12: 8177 | F12: 8716 | G12: =ROUND(E12/D12,1) -> 107.6
A13: 500101171 | B13: YouBike2.0_行天宮 | C13: 中山區 | D13: 20 | E13: 1904 | F13: 1914 | G13: =ROUND(E13/D13,1) -> 95.2
A14: 500101189 | B14: YouBike2.0_捷運民權西路站(9號出口) | C14: 中山區 | D14: 76 | E14: 7936 | F14: 8277 | G14: =ROUND(E14/D14,1) -> 104.4
A15: 500101206 | B15: YouBike2.0_花博公園 | C15: 中山區 | D15: 32 | E15: 3259 | F15: 3201 | G15: =ROUND(E15/D15,1) -> 101.8
A16: 500101232 | B16: YouBike2.0_捷運南京三民站 | C16: 松山區 | D16: 48 | E16: 4237 | F16: 4218 | G16: =ROUND(E16/D16,1) -> 88.3
... A44: 500101920 | B44: YouBike2.0_動物園 | C44: 文山區 | D44: 30 | E44: 2538 | F44: 2729 | G44: =ROUND(E44/D44,1) -> 84.6

Sheet 篩選練習
A1: 篩選與排序練習
A2: 到「清理後」工作表操作，把答案填在 C 欄；D 欄用公式驗算
A4: 題號 | B4: 題目 | C4: 你的答案 | D4: 驗算（公式）
A5: 1 | B5: 依「9月借車次數」由大到小排序，借車最多的是哪一站？ | D5: =INDEX(清理後!$B$5:$B$44,MATCH(MAX(清理後!$E$5:$E$44),清理後!$E$5:$E$44,0)) -> YouBike2.0_捷運大安站
A6: 2 | B6: 篩選「行政區＝大安區」，共有幾站？ | D6: =COUNTIF(清理後!$C$5:$C$44,"大安區") -> 5
A7: 3 | B7: 篩選「車柱數 ≥ 50」，共有幾站？ | D7: =COUNTIF(清理後!$D$5:$D$44,">=50") -> 9
A8: 4 | B8: 多層排序：先依行政區、再依借車次數由大到小。文山區借車最多的站是？ | D8: =INDEX(清理後!$B$5:$B$44,MATCH(_xlfn.MAXIFS(清理後!$E$5:$E$44,清理後!$C$5:$C$44,"文山區"),清理後!$E$5:$E$44,0)) -> YouBike2.0_捷運木柵站
A9: 5 | B9: 進階篩選：信義區「且」借車次數 ≥ 4000 的站有幾站？（條件區域見下方） | D9: =COUNTIFS(清理後!$C$5:$C$44,"信義區",清理後!$E$5:$E$44,">=4000") -> 2
A12: 進階篩選條件區域範例 | D12: 進階篩選：資料 → 進階 → 資料範圍選「清理後」整張表，準則範圍選 A13:B14。 同一列的條件是「且（AND）」，寫在不同列是「或（OR）」。
A13: 行政區 | B13: 9月借車次數
A14: 信義區 | B14: >=4000

Sheet 統計
A1: 統計函數應用
A2: 所有數字都由公式計算；改「清理後」的資料，這裡會自動更新
A4: 統計項目 | B4: 借車次數 | C4: 公式說明 | G4: 平均 vs 中位數：哪一個比較能代表「一般人」？
A5: 平均數 | B5: =ROUND(AVERAGE(清理後!$E$5:$E$44),0) -> 3870 | C5: AVERAGE | G5: 員工 | H5: 月薪
A6: 中位數 | B6: =MEDIAN(清理後!$E$5:$E$44) -> 3240.5 | C6: MEDIAN | G6: 員工1 | H6: 30000
A7: 標準差 | B7: =ROUND(STDEV(清理後!$E$5:$E$44),0) -> 2081 | C7: STDEV：數字越大代表各站差異越大 | G7: 員工2 | H7: 30000
A8: 最大值 | B8: =MAX(清理後!$E$5:$E$44) -> 8885 | C8: MAX | G8: 員工3 | H8: 30000
A9: 最小值 | B9: =MIN(清理後!$E$5:$E$44) -> 1216 | C9: MIN | G9: 員工4 | H9: 30000
A10: 站點數 | B10: =COUNT(清理後!$E$5:$E$44) -> 40 | C10: COUNT | G10: 員工5 | H10: 30000
A11: 借車 ≥ 4000 的站數 | B11: =COUNTIF(清理後!$E$5:$E$44,">=4000") -> 13 | C11: COUNTIF(範圍,">=4000") | G11: 員工6 | H11: 30000
A12: 最常見的車柱數（眾數） | B12: =MODE(清理後!$D$5:$D$44) -> 28 | C12: MODE（看車柱數） | G12: 員工7 | H12: 30000
G13: 員工8 | H13: 30000
G14: 員工9 | H14: 30000
A15: 各行政區統計（圖表的資料來源） | G15: 員工10 | H15: 1000000
A16: 行政區 | B16: 站點數 COUNTIF | C16: 借車總數 SUMIF | D16: 平均每站 AVERAGEIF | E16: 車柱總數 SUMIF
A17: 中正區 | B17: =COUNTIF(清理後!$C$5:$C$44,A17) -> 4 | C17: =SUMIF(清理後!$C$5:$C$44,A17,清理後!$E$5:$E$44) -> 21757 | D17: =ROUND(AVERAGEIF(清理後!$C$5:$C$44,A17,清理後!$E$5:$E$44),0) -> 5439 | E17: =SUMIF(清理後!$C$5:$C$44,A17,清理後!$D$5:$D$44) -> 210 | G17: 平均月薪 | H17: =AVERAGE(H6:H15) -> 127000
A18: 大同區 | B18: =COUNTIF(清理後!$C$5:$C$44,A18) -> 3 | C18: =SUMIF(清理後!$C$5:$C$44,A18,清理後!$E$5:$E$44) -> 7371 | D18: =ROUND(AVERAGEIF(清理後!$C$5:$C$44,A18,清理後!$E$5:$E$44),0) -> 2457 | E18: =SUMIF(清理後!$C$5:$C$44,A18,清理後!$D$5:$D$44) -> 92 | G18: 中位數月薪 | H18: =MEDIAN(H6:H15) -> 30000
A19: 中山區 | B19: =COUNTIF(清理後!$C$5:$C$44,A19) -> 4 | C19: =SUMIF(清理後!$C$5:$C$44,A19,清理後!$E$5:$E$44) -> 21276 | D19: =ROUND(AVERAGEIF(清理後!$C$5:$C$44,A19,清理後!$E$5:$E$44),0) -> 5319 | E19: =SUMIF(清理後!$C$5:$C$44,A19,清理後!$D$5:$D$44) -> 204
A20: 松山區 | B20: =COUNTIF(清理後!$C$5:$C$44,A20) -> 2 | C20: =SUMIF(清理後!$C$5:$C$44,A20,清理後!$E$5:$E$44) -> 9355 | D20: =ROUND(AVERAGEIF(清理後!$C$5:$C$44,A20,清理後!$E$5:$E$44),0) -> 4678 | E20: =SUMIF(清理後!$C$5:$C$44,A20,清理後!$D$5:$D$44) -> 116 | G20: 9 人月薪 3 萬、1 人 100 萬：平均被拉高到約 12.7 萬，中位數才是 3 萬。 有極端值時，中位數比平均數更能代表「典型值」。
A21: 大安區 | B21: =COUNTIF(清理後!$C$5:$C$44,A21) -> 5 | C21: =SUMIF(清理後!$C$5:$C$44,A21,清理後!$E$5:$E$44) -> 28567 | D21: =ROUND(AVERAGEIF(清理後!$C$5:$C$44,A21,清理後!$E$5:$E$44),0) -> 5713 | E21: =SUMIF(清理後!$C$5:$C$44,A21,清理後!$D$5:$D$44) -> 204
A22: 萬華區 | B22: =COUNTIF(清理後!$C$5:$C$44,A22) -> 3 | C22: =SUMIF(清理後!$C$5:$C$44,A22,清理後!$E$5:$E$44) -> 8971 | D22: =ROUND(AVERAGEIF(清理後!$C$5:$C$44,A22,清理後!$E$5:$E$44),0) -> 2990 | E22: =SUMIF(清理後!$C$5:$C$44,A22,清理後!$D$5:$D$44) -> 120
A23: 信義區 | B23: =COUNTIF(清理後!$C$5:$C$44,A23) -> 4 | C23: =SUMIF(清理後!$C$5:$C$44,A23,清理後!$E$5:$E$44) -> 15779 | D23: =ROUND(AVERAGEIF(清理後!$C$5:$C$44,A23,清理後!$E$5:$E$44),0) -> 3945 | E23: =SUMIF(清理後!$C$5:$C$44,A23,清理後!$D$5:$D$44) -> 156
A24: 士林區 | B24: =COUNTIF(清理後!$C$5:$C$44,A24) -> 3 | C24: =SUMIF(清理後!$C$5:$C$44,A24,清理後!$E$5:$E$44) -> 9513 | D24: =ROUND(AVERAGEIF(清理後!$C$5:$C$44,A24,清理後!$E$5:$E$44),0) -> 3171 | E24: =SUMIF(清理後!$C$5:$C$44,A24,清理後!$D$5:$D$44) -> 106
A25: 北投區 | B25: =COUNTIF(清理後!$C$5:$C$44,A25) -> 3 | C25: =SUMIF(清理後!$C$5:$C$44,A25,清理後!$E$5:$E$44) -> 5554 | D25: =ROUND(AVERAGEIF(清理後!$C$5:$C$44,A25,清理後!$E$5:$E$44),0) -> 1851 | E25: =SUMIF(清理後!$C$5:$C$44,A25,清理後!$D$5:$D$44) -> 92
A26: 內湖區 | B26: =COUNTIF(清理後!$C$5:$C$44,A26) -> 2 | C26: =SUMIF(清理後!$C$5:$C$44,A26,清理後!$E$5:$E$44) -> 9128 | D26: =ROUND(AVERAGEIF(清理後!$C$5:$C$44,A26,清理後!$E$5:$E$44),0) -> 4564 | E26: =SUMIF(清理後!$C$5:$C$44,A26,清理後!$D$5:$D$44) -> 104
A27: 南港區 | B27: =COUNTIF(清理後!$C$5:$C$44,A27) -> 3 | C27: =SUMIF(清理後!$C$5:$C$44,A27,清理後!$E$5:$E$44) -> 7460 | D27: =ROUND(AVERAGEIF(清理後!$C$5:$C$44,A27,清理後!$E$5:$E$44),0) -> 2487 | E27: =SUMIF(清理後!$C$5:$C$44,A27,清理後!$D$5:$D$44) -> 122
A28: 文山區 | B28: =COUNTIF(清理後!$C$5:$C$44,A28) -> 4 | C28: =SUMIF(清理後!$C$5:$C$44,A28,清理後!$E$5:$E$44) -> 10073 | D28: =ROUND(AVERAGEIF(清理後!$C$5:$C$44,A28,清理後!$E$5:$E$44),0) -> 2518 | E28: =SUMIF(清理後!$C$5:$C$44,A28,清理後!$D$5:$D$44) -> 138
A29: 合計 | B29: =SUM(B17:B28) -> 40 | C29: =SUM(C17:C28) -> 154804 | E29: =SUM(E17:E28) -> 1664

Sheet 時段資料
A1: 平日 vs 假日：每小時借車次數（全市合計，模擬）
A2: 用來畫折線圖、觀察通勤尖峰
A4: 時段 | B4: 平日 | C4: 假日
A5: 00:00 | B5: 261 | C5: 266
A6: 01:00 | B6: 226 | C6: 200
A7: 02:00 | B7: 244 | C7: 176
A8: 03:00 | B8: 293 | C8: 167
A9: 04:00 | B9: 337 | C9: 186
A10: 05:00 | B10: 387 | C10: 185
A11: 06:00 | B11: 669 | C11: 205
A12: 07:00 | B12: 2644 | C12: 224
A13: 08:00 | B13: 4531 | C13: 289
A14: 09:00 | B14: 2626 | C14: 403
A15: 10:00 | B15: 910 | C15: 624
A16: 11:00 | B16: 885 | C16: 1001
... A28: 23:00 | B28: 289 | C28: 231

Sheet 圖表
A1: 資料視覺化：選對圖表類型
A2: 長條圖比大小、折線圖看趨勢、散佈圖看兩個變數的關係
K22: ⚠️ 資料說謊：同一份資料，Y 軸起點不同
K38: 右圖把 Y 軸從 1500 開始，各區「平均每站借車數」的差距看起來被放大好幾倍。看圖表時，先看 Y 軸從哪裡開始！

Sheet 洞見範例
A1: 從圖表到洞見：言之有據的寫法
A2: 洞見 = 觀察到的現象 ＋ 數字證據 ＋ 可能的原因（注意相關 ≠ 因果）
B4: 只是描述（不夠好） | C4: 言之有據的洞見（好）
A5: 洞見 1 | B5: 大安區借車最多。 | C5: 大安區借車總數全市最高（見「統計」工作表），而且站點數也最多；大安區有臺大、師大與多個捷運站，學生與通勤族多，可能是借車量高的原因。
A6: 洞見 2 | B6: 早上和晚上借車多。 | C6: 平日借車在 08:00 與 18:00 形成兩個尖峰，假日則在下午較平均，顯示平日 YouBike 主要用於上下班、上下學的通勤接駁。
A7: 洞見 3 | B7: 車柱多的站借車多。 | C7: 散佈圖顯示車柱數與借車次數呈正相關（趨勢線向右上），但這不代表「多裝車柱就會增加借車」，也可能是本來人多的地點才會設置較大的站。
